Workbook

Sheet BOM_full
B2: BOM
I3: 730 | J3: 0
B5: Cluster | D5: Part Number | E5: Product | F5: Quantity | G5: Metric | H5: Price (USD) | I5: Term | J5: Descuento | K5: Month 1 | L5: Month 2 | M5: Month 3 | N5: Month 4 | O5: Month 5 | P5: Month 6 | Q5: Month 7 | R5: Month 8 | S5: Month 9 | T5: Month 10 | U5: Month 11 | V5: Month 12 | W5: Month 13 | X5: Month 14 | Y5: Month 15 | Z5: Month 16 | AA5: Month 17 | AB5: Month 18 | AC5: Month 19 | AD5: Month 20 | AE5: Month 21 | AF5: Month 22 | AG5: Month 23 | AH5: Month 24 | AI5: Month 25 | AJ5: Month 26 | AK5: Month 27 | AL5: Month 28 | AM5: Month 29 | AN5: Month 30 | AO5: Month 31 | AP5: Month 32 | AQ5: Month 33 | AR5: Month 34 | AS5: Month 35 | AT5: Month 36
B6: OCVS | C6: Computo / Storage | D6: B93290 | E6: Oracle Cloud VMware Solution - BM.DenseIO2.52 - 3 Year Commit | F6: =4*52 -> 208 | G6: OCPU Per Hour | H6: 0.132 | I6: =$I$3 -> 730 | J6: 0 | K6: =$F$6*$H$6*$I$6*(1-$J6)*Rampa!B14 -> 20042.88 | L6: =$F$6*$H$6*$I$6*(1-$J6)*Rampa!C14 -> 20042.88 | M6: =$F$6*$H$6*$I$6*(1-$J6)*Rampa!D14 -> 20042.88 | N6: =$F$6*$H$6*$I$6*(1-$J6)*Rampa!E14 -> 20042.88 | O6: =$F$6*$H$6*$I$6*(1-$J6)*Rampa!F14 -> 20042.88 | P6: =$F$6*$H$6*$I$6*(1-$J6)*Rampa!G14 -> 20042.88 | Q6: =$F$6*$H$6*$I$6*(1-$J6)*Rampa!H14 -> 20042.88 | R6: =$F$6*$H$6*$I$6*(1-$J6)*Rampa!I14 -> 20042.88 | ... AT6: =$F$6*$H$6*$I$6*(1-$J6)*Rampa!AK14 -> 20042.88
D7: B91961 | E7: Oracle Cloud Infrastructure - Block Volume Storage | F7: 172000 | G7: Gigabyte Storage Capacity Per Month | H7: 0.0255 | I7: 1 | J7: 0.05 | K7: =$F$7*$H$7*$I$7*(1-$J$7)*Rampa!B14 -> 4166.7 | L7: =$F$7*$H$7*$I$7*(1-$J$7)*Rampa!C14 -> 4166.7 | M7: =$F$7*$H$7*$I$7*(1-$J$7)*Rampa!D14 -> 4166.7 | N7: =$F$7*$H$7*$I$7*(1-$J$7)*Rampa!E14 -> 4166.7 | O7: =$F$7*$H$7*$I$7*(1-$J$7)*Rampa!F14 -> 4166.7 | P7: =$F$7*$H$7*$I$7*(1-$J$7)*Rampa!G14 -> 4166.7 | Q7: =$F$7*$H$7*$I$7*(1-$J$7)*Rampa!H14 -> 4166.7 | R7: =$F$7*$H$7*$I$7*(1-$J$7)*Rampa!I14 -> 4166.7 | ... AT7: =$F$7*$H$7*$I$7*(1-$J$7)*Rampa!AK14 -> 4166.7
D8: B91962 | E8: Oracle Cloud Infrastructure - Block Volume Performance | F8: 1720000 | G8: Performance Units Per Gigabyte Per Month | H8: 0.0017 | I8: 1 | J8: 0.05 | K8: =$F$8*$H$8*$I$8*(1-$J$8)*Rampa!B14 -> 2777.8 | L8: =$F$8*$H$8*$I$8*(1-$J$8)*Rampa!C14 -> 2777.8 | M8: =$F$8*$H$8*$I$8*(1-$J$8)*Rampa!D14 -> 2777.8 | N8: =$F$8*$H$8*$I$8*(1-$J$8)*Rampa!E14 -> 2777.8 | O8: =$F$8*$H$8*$I$8*(1-$J$8)*Rampa!F14 -> 2777.8 | P8: =$F$8*$H$8*$I$8*(1-$J$8)*Rampa!G14 -> 2777.8 | Q8: =$F$8*$H$8*$I$8*(1-$J$8)*Rampa!H14 -> 2777.8 | R8: =$F$8*$H$8*$I$8*(1-$J$8)*Rampa!I14 -> 2777.8 | ... AT8: =$F$8*$H$8*$I$8*(1-$J$8)*Rampa!AK14 -> 2777.8
D9: B91628 | E9: Oracle Cloud Infrastructure - Object Storage - Storage | F9: 50000 | G9: Gigabyte Storage Capacity Per Month | H9: 0.0255 | I9: 1 | J9: 0.05 | K9: =$F$9*$H$9*$I$9*(1-$J$9)*Rampa!B14 -> 1211.25 | L9: =$F$9*$H$9*$I$9*(1-$J$9)*Rampa!C14 -> 1211.25 | M9: =$F$9*$H$9*$I$9*(1-$J$9)*Rampa!D14 -> 1211.25 | N9: =$F$9*$H$9*$I$9*(1-$J$9)*Rampa!E14 -> 1211.25 | O9: =$F$9*$H$9*$I$9*(1-$J$9)*Rampa!F14 -> 1211.25 | P9: =$F$9*$H$9*$I$9*(1-$J$9)*Rampa!G14 -> 1211.25 | Q9: =$F$9*$H$9*$I$9*(1-$J$9)*Rampa!H14 -> 1211.25 | R9: =$F$9*$H$9*$I$9*(1-$J$9)*Rampa!I14 -> 1211.25 | ... AT9: =$F$9*$H$9*$I$9*(1-$J$9)*Rampa!AK14 -> 1211.25
D10: B93000 | E10: Oracle Cloud Infrastructure - Infrequent Access - Storage | F10: 75000 | G10: Gigabyte Storage Capacity Per Month | H10: 0.01 | I10: 1 | J10: 0.05 | K10: =$F$10*$H$10*$I$10*(1-$J$10)*Rampa!B14 -> 712.5 | L10: =$F$10*$H$10*$I$10*(1-$J$10)*Rampa!C14 -> 712.5 | M10: =$F$10*$H$10*$I$10*(1-$J$10)*Rampa!D14 -> 712.5 | N10: =$F$10*$H$10*$I$10*(1-$J$10)*Rampa!E14 -> 712.5 | O10: =$F$10*$H$10*$I$10*(1-$J$10)*Rampa!F14 -> 712.5 | P10: =$F$10*$H$10*$I$10*(1-$J$10)*Rampa!G14 -> 712.5 | Q10: =$F$10*$H$10*$I$10*(1-$J$10)*Rampa!H14 -> 712.5 | R10: =$F$10*$H$10*$I$10*(1-$J$10)*Rampa!I14 -> 712.5 | ... AT10: =$F$10*$H$10*$I$10*(1-$J$10)*Rampa!AK14 -> 712.5
D11: B91627 | E11: Oracle Cloud Infrastructure - Object Storage - Request | F11: =ROUNDUP(F9*0.01,0) -> 500 | G11: 10K Requests Per Month | H11: 0.0034 | I11: 1 | J11: 0.05 | K11: =$F$11*$H$11*$I$11*(1-$J$11)*Rampa!B14 -> 1.615 | L11: =$F$11*$H$11*$I$11*(1-$J$11)*Rampa!C14 -> 1.615 | M11: =$F$11*$H$11*$I$11*(1-$J$11)*Rampa!D14 -> 1.615 | N11: =$F$11*$H$11*$I$11*(1-$J$11)*Rampa!E14 -> 1.615 | O11: =$F$11*$H$11*$I$11*(1-$J$11)*Rampa!F14 -> 1.615 | P11: =$F$11*$H$11*$I$11*(1-$J$11)*Rampa!G14 -> 1.615 | Q11: =$F$11*$H$11*$I$11*(1-$J$11)*Rampa!H14 -> 1.615 | R11: =$F$11*$H$11*$I$11*(1-$J$11)*Rampa!I14 -> 1.615 | ... AT11: =$F$11*$H$11*$I$11*(1-$J$11)*Rampa!AK14 -> 1.615
C12: Networking | D12: B88326 | E12: Oracle Cloud Infrastructure - FastConnect 10 Gbps | F12: 2 | G12: Port Hour | H12: 1.275 | I12: =$I$3 -> 730 | J12: 0.05 | K12: =$F$12*$H$12*$I$12*(1-$J$12)*Rampa!B20 -> 0 | L12: =$F$12*$H$12*$I$12*(1-$J$12)*Rampa!C20 -> 1768.425 | M12: =$F$12*$H$12*$I$12*(1-$J$12)*Rampa!D20 -> 1768.425 | N12: =$F$12*$H$12*$I$12*(1-$J$12)*Rampa!E20 -> 1768.425 | O12: =$F$12*$H$12*$I$12*(1-$J$12)*Rampa!F20 -> 1768.425 | P12: =$F$12*$H$12*$I$12*(1-$J$12)*Rampa!G20 -> 1768.425 | Q12: =$F$12*$H$12*$I$12*(1-$J$12)*Rampa!H20 -> 1768.425 | R12: =$F$12*$H$12*$I$12*(1-$J$12)*Rampa!I20 -> 1768.425 | ... AT12: =$F$12*$H$12*$I$12*(1-$J$12)*Rampa!AK20 -> 1768.425
B13: OCI Kubernetes Engine | C13: Computo | D13: B96545 | E13: Oracle Container Engine for Kubernetes - Enhanced Cluster | F13: 1 | G13: Cluster Per Hour | H13: 0.1 | I13: 730 | J13: 0.05 | K13: =$F$13*$H$13*$I$13*(1-$J$13)*Rampa!B15 -> 0 | L13: =$F$13*$H$13*$I$13*(1-$J$13)*Rampa!C15 -> 69.35 | M13: =$F$13*$H$13*$I$13*(1-$J$13)*Rampa!D15 -> 69.35 | N13: =$F$13*$H$13*$I$13*(1-$J$13)*Rampa!E15 -> 69.35 | O13: =$F$13*$H$13*$I$13*(1-$J$13)*Rampa!F15 -> 69.35 | P13: =$F$13*$H$13*$I$13*(1-$J$13)*Rampa!G15 -> 69.35 | Q13: =$F$13*$H$13*$I$13*(1-$J$13)*Rampa!H15 -> 69.35 | R13: =$F$13*$H$13*$I$13*(1-$J$13)*Rampa!I15 -> 69.35 | ... AT13: =$F$13*$H$13*$I$13*(1-$J$13)*Rampa!AK15 -> 69.35
D14: B94176 | E14: Oracle Cloud Infrastructure - Compute - Standard - X9 | F14: 48 | G14: OCPU Per Hour | H14: 0.04 | I14: =$I$3 -> 730 | J14: 0.05 | K14: =$F$14*$H$14*$I$14*(1-$J$14)*Rampa!B15 -> 0 | L14: =$F$14*$H$14*$I$14*(1-$J$14)*Rampa!C15 -> 1331.52 | M14: =$F$14*$H$14*$I$14*(1-$J$14)*Rampa!D15 -> 1331.52 | N14: =$F$14*$H$14*$I$14*(1-$J$14)*Rampa!E15 -> 1331.52 | O14: =$F$14*$H$14*$I$14*(1-$J$14)*Rampa!F15 -> 1331.52 | P14: =$F$14*$H$14*$I$14*(1-$J$14)*Rampa!G15 -> 1331.52 | Q14: =$F$14*$H$14*$I$14*(1-$J$14)*Rampa!H15 -> 1331.52 | R14: =$F$14*$H$14*$I$14*(1-$J$14)*Rampa!I15 -> 1331.52 | ... AT14: =$F$14*$H$14*$I$14*(1-$J$14)*Rampa!AK15 -> 1331.52
D15: B94177 | E15: Oracle Cloud Infrastructure - Compute - Standard - Memory | F15: 360 | G15: GB per hour | H15: 0.0015 | I15: =$I$3 -> 730 | J15: 0.05 | K15: =$F$15*$H$15*$I$15*(1-$J$15)*Rampa!B15 -> 0 | L15: =$F$15*$H$15*$I$15*(1-$J$15)*Rampa!C15 -> 374.49 | M15: =$F$15*$H$15*$I$15*(1-$J$15)*Rampa!D15 -> 374.49 | N15: =$F$15*$H$15*$I$15*(1-$J$15)*Rampa!E15 -> 374.49 | O15: =$F$15*$H$15*$I$15*(1-$J$15)*Rampa!F15 -> 374.49 | P15: =$F$15*$H$15*$I$15*(1-$J$15)*Rampa!G15 -> 374.49 | Q15: =$F$15*$H$15*$I$15*(1-$J$15)*Rampa!H15 -> 374.49 | R15: =$F$15*$H$15*$I$15*(1-$J$15)*Rampa!I15 -> 374.49 | ... AT15: =$F$15*$H$15*$I$15*(1-$J$15)*Rampa!AK15 -> 374.49
D16: B91961 | E16: Oracle Cloud Infrastructure - Block Volume Storage | F16: 900 | G16: Gigabyte Storage Capacity Per Month | H16: 0.0255 | I16: 1 | J16: 0.05 | K16: =$F$16*$H$16*$I$16*(1-$J$16)*Rampa!B15 -> 0 | L16: =$F$16*$H$16*$I$16*(1-$J$16)*Rampa!C15 -> 21.8025 | M16: =$F$16*$H$16*$I$16*(1-$J$16)*Rampa!D15 -> 21.8025 | N16: =$F$16*$H$16*$I$16*(1-$J$16)*Rampa!E15 -> 21.8025 | O16: =$F$16*$H$16*$I$16*(1-$J$16)*Rampa!F15 -> 21.8025 | P16: =$F$16*$H$16*$I$16*(1-$J$16)*Rampa!G15 -> 21.8025 | Q16: =$F$16*$H$16*$I$16*(1-$J$16)*Rampa!H15 -> 21.8025 | R16: =$F$16*$H$16*$I$16*(1-$J$16)*Rampa!I15 -> 21.8025 | ... AT16: =$F$16*$H$16*$I$16*(1-$J$16)*Rampa!AK15 -> 21.8025
D17: B91962 | E17: Oracle Cloud Infrastructure - Block Volume Performance | F17: 9000 | G17: Performance Units Per Gigabyte Per Month | H17: 0.0017 | I17: 1 | J17: 0.05 | K17: =$F$17*$H$17*$I$17*(1-$J$17)*Rampa!B15 -> 0 | L17: =$F$17*$H$17*$I$17*(1-$J$17)*Rampa!C15 -> 14.535 | M17: =$F$17*$H$17*$I$17*(1-$J$17)*Rampa!D15 -> 14.535 | N17: =$F$17*$H$17*$I$17*(1-$J$17)*Rampa!E15 -> 14.535 | O17: =$F$17*$H$17*$I$17*(1-$J$17)*Rampa!F15 -> 14.535 | P17: =$F$17*$H$17*$I$17*(1-$J$17)*Rampa!G15 -> 14.535 | Q17: =$F$17*$H$17*$I$17*(1-$J$17)*Rampa!H15 -> 14.535 | R17: =$F$17*$H$17*$I$17*(1-$J$17)*Rampa!I15 -> 14.535 | ... AT17: =$F$17*$H$17*$I$17*(1-$J$17)*Rampa!AK15 -> 14.535
B18: PostgreSQL | C18: PRD1 | D18: B99060 | E18: Oracle Cloud Infrastructure Database with PostgreSQL - X86 | F18: 8 | G18: OCPU Per Hour | H18: 0.098 | I18: 730 | J18: 0.05 | K18: =$F$18*$H$18*$I$18*(1-$J$18)*Rampa!B16 -> 0 | L18: =$F$18*$H$18*$I$18*(1-$J$18)*Rampa!C16 -> 543.704 | M18: =$F$18*$H$18*$I$18*(1-$J$18)*Rampa!D16 -> 543.704 | N18: =$F$18*$H$18*$I$18*(1-$J$18)*Rampa!E16 -> 543.704 | O18: =$F$18*$H$18*$I$18*(1-$J$18)*Rampa!F16 -> 543.704 | P18: =$F$18*$H$18*$I$18*(1-$J$18)*Rampa!G16 -> 543.704 | Q18: =$F$18*$H$18*$I$18*(1-$J$18)*Rampa!H16 -> 543.704 | R18: =$F$18*$H$18*$I$18*(1-$J$18)*Rampa!I16 -> 543.704 | ... AT18: =$F$18*$H$18*$I$18*(1-$J$18)*Rampa!AK16 -> 543.704
D19: B99062 | E19: Oracle Cloud Infrastructure Database Optimized Storage | F19: 320 | G19: Gigabyte Storage Capacity Per Month | H19: 0.072 | I19: 1 | J19: 0.05 | K19: =$F$19*$H$19*$I$19*(1-$J$19)*Rampa!B16 -> 0 | L19: =$F$19*$H$19*$I$19*(1-$J$19)*Rampa!C16 -> 21.888 | M19: =$F$19*$H$19*$I$19*(1-$J$19)*Rampa!D16 -> 21.888 | N19: =$F$19*$H$19*$I$19*(1-$J$19)*Rampa!E16 -> 21.888 | O19: =$F$19*$H$19*$I$19*(1-$J$19)*Rampa!F16 -> 21.888 | P19: =$F$19*$H$19*$I$19*(1-$J$19)*Rampa!G16 -> 21.888 | Q19: =$F$19*$H$19*$I$19*(1-$J$19)*Rampa!H16 -> 21.888 | R19: =$F$19*$H$19*$I$19*(1-$J$19)*Rampa!I16 -> 21.888 | ... AT19: =$F$19*$H$19*$I$19*(1-$J$19)*Rampa!AK16 -> 21.888
D20: B93113 | E20: Oracle Cloud Infrastructure-Compute-Standard-E4 | F20: 8 | G20: OCPU Per Hour | H20: 0.025 | I20: 730 | J20: 0.05 | K20: =$F$20*$H$20*$I$20*(1-$J$20)*Rampa!B16 -> 0 | L20: =$F$20*$H$20*$I$20*(1-$J$20)*Rampa!C16 -> 138.7 | M20: =$F$20*$H$20*$I$20*(1-$J$20)*Rampa!D16 -> 138.7 | N20: =$F$20*$H$20*$I$20*(1-$J$20)*Rampa!E16 -> 138.7 | O20: =$F$20*$H$20*$I$20*(1-$J$20)*Rampa!F16 -> 138.7 | P20: =$F$20*$H$20*$I$20*(1-$J$20)*Rampa!G16 -> 138.7 | Q20: =$F$20*$H$20*$I$20*(1-$J$20)*Rampa!H16 -> 138.7 | R20: =$F$20*$H$20*$I$20*(1-$J$20)*Rampa!I16 -> 138.7 | ... AT20: =$F$20*$H$20*$I$20*(1-$J$20)*Rampa!AK16 -> 138.7
D21: B93114 | E21: Oracle Cloud Infrastructure-Compute-Standard-E4-Memory | F21: 128 | G21: Gigabyte Per Hour | H21: 0.0015 | I21: 730 | J21: 0.05 | K21: =$F$21*$H$21*$I$21*(1-$J$21)*Rampa!B16 -> 0 | L21: =$F$21*$H$21*$I$21*(1-$J$21)*Rampa!C16 -> 133.152 | M21: =$F$21*$H$21*$I$21*(1-$J$21)*Rampa!D16 -> 133.152 | N21: =$F$21*$H$21*$I$21*(1-$J$21)*Rampa!E16 -> 133.152 | O21: =$F$21*$H$21*$I$21*(1-$J$21)*Rampa!F16 -> 133.152 | P21: =$F$21*$H$21*$I$21*(1-$J$21)*Rampa!G16 -> 133.152 | Q21: =$F$21*$H$21*$I$21*(1-$J$21)*Rampa!H16 -> 133.152 | R21: =$F$21*$H$21*$I$21*(1-$J$21)*Rampa!I16 -> 133.152 | ... AT21: =$F$21*$H$21*$I$21*(1-$J$21)*Rampa!AK16 -> 133.152
D22: B91961 | E22: Oracle Cloud Infrastructure - Block Volume Storage | F22: 320 | G22: Gigabyte Storage Capacity Per Month | H22: 0.0255 | I22: 1 | J22: 0.05 | K22: =$F$22*$H$22*$I$22*(1-$J$22)*Rampa!B16 -> 0 | L22: =$F$22*$H$22*$I$22*(1-$J$22)*Rampa!C16 -> 7.752 | M22: =$F$22*$H$22*$I$22*(1-$J$22)*Rampa!D16 -> 7.752 | N22: =$F$22*$H$22*$I$22*(1-$J$22)*Rampa!E16 -> 7.752 | O22: =$F$22*$H$22*$I$22*(1-$J$22)*Rampa!F16 -> 7.752 | P22: =$F$22*$H$22*$I$22*(1-$J$22)*Rampa!G16 -> 7.752 | Q22: =$F$22*$H$22*$I$22*(1-$J$22)*Rampa!H16 -> 7.752 | R22: =$F$22*$H$22*$I$22*(1-$J$22)*Rampa!I16 -> 7.752 | ... AT22: =$F$22*$H$22*$I$22*(1-$J$22)*Rampa!AK16 -> 7.752
D23: B91962 | E23: Oracle Cloud Infrastructure - Block Volume Performance | F23: 38400 | G23: Performance Units Per Gigabyte Per Month | H23: 0.0017 | I23: 1 | J23: 0.05 | K23: =$F$23*$H$23*$I$23*(1-$J$23)*Rampa!B16 -> 0 | L23: =$F$23*$H$23*$I$23*(1-$J$23)*Rampa!C16 -> 62.016 | M23: =$F$23*$H$23*$I$23*(1-$J$23)*Rampa!D16 -> 62.016 | N23: =$F$23*$H$23*$I$23*(1-$J$23)*Rampa!E16 -> 62.016 | O23: =$F$23*$H$23*$I$23*(1-$J$23)*Rampa!F16 -> 62.016 | P23: =$F$23*$H$23*$I$23*(1-$J$23)*Rampa!G16 -> 62.016 | Q23: =$F$23*$H$23*$I$23*(1-$J$23)*Rampa!H16 -> 62.016 | R23: =$F$23*$H$23*$I$23*(1-$J$23)*Rampa!I16 -> 62.016 | ... AT23: =$F$23*$H$23*$I$23*(1-$J$23)*Rampa!AK16 -> 62.016
C24: PRD2 | D24: B99060 | E24: Oracle Cloud Infrastructure Database with PostgreSQL - X86 | F24: 8 | G24: OCPU Per Hour | H24: 0.098 | I24: 730 | J24: 0.05 | K24: =$F$24*$H$24*$I$24*(1-$J$24)*Rampa!B17 -> 0 | L24: =$F$24*$H$24*$I$24*(1-$J$24)*Rampa!C17 -> 543.704 | M24: =$F$24*$H$24*$I$24*(1-$J$24)*Rampa!D17 -> 543.704 | N24: =$F$24*$H$24*$I$24*(1-$J$24)*Rampa!E17 -> 543.704 | O24: =$F$24*$H$24*$I$24*(1-$J$24)*Rampa!F17 -> 543.704 | P24: =$F$24*$H$24*$I$24*(1-$J$24)*Rampa!G17 -> 543.704 | Q24: =$F$24*$H$24*$I$24*(1-$J$24)*Rampa!H17 -> 543.704 | R24: =$F$24*$H$24*$I$24*(1-$J$24)*Rampa!I17 -> 543.704 | ... AT24: =$F$24*$H$24*$I$24*(1-$J$24)*Rampa!AK17 -> 543.704
D25: B99062 | E25: Oracle Cloud Infrastructure Database Optimized Storage | F25: 413 | G25: Gigabyte Storage Capacity Per Month | H25: 0.072 | I25: 1 | J25: 0.05 | K25: =$F$25*$H$25*$I$25*(1-$J$25)*Rampa!B17 -> 0 | L25: =$F$25*$H$25*$I$25*(1-$J$25)*Rampa!C17 -> 28.2492 | M25: =$F$25*$H$25*$I$25*(1-$J$25)*Rampa!D17 -> 28.2492 | N25: =$F$25*$H$25*$I$25*(1-$J$25)*Rampa!E17 -> 28.2492 | O25: =$F$25*$H$25*$I$25*(1-$J$25)*Rampa!F17 -> 28.2492 | P25: =$F$25*$H$25*$I$25*(1-$J$25)*Rampa!G17 -> 28.2492 | Q25: =$F$25*$H$25*$I$25*(1-$J$25)*Rampa!H17 -> 28.2492 | R25: =$F$25*$H$25*$I$25*(1-$J$25)*Rampa!I17 -> 28.2492 | ... AT25: =$F$25*$H$25*$I$25*(1-$J$25)*Rampa!AK17 -> 28.2492
D26: B93113 | E26: Oracle Cloud Infrastructure-Compute-Standard-E4 | F26: 8 | G26: OCPU Per Hour | H26: 0.025 | I26: 730 | J26: 0.05 | K26: =$F$26*$H$26*$I$26*(1-$J$26)*Rampa!B17 -> 0 | L26: =$F$26*$H$26*$I$26*(1-$J$26)*Rampa!C17 -> 138.7 | M26: =$F$26*$H$26*$I$26*(1-$J$26)*Rampa!D17 -> 138.7 | N26: =$F$26*$H$26*$I$26*(1-$J$26)*Rampa!E17 -> 138.7 | O26: =$F$26*$H$26*$I$26*(1-$J$26)*Rampa!F17 -> 138.7 | P26: =$F$26*$H$26*$I$26*(1-$J$26)*Rampa!G17 -> 138.7 | Q26: =$F$26*$H$26*$I$26*(1-$J$26)*Rampa!H17 -> 138.7 | R26: =$F$26*$H$26*$I$26*(1-$J$26)*Rampa!I17 -> 138.7 | ... AT26: =$F$26*$H$26*$I$26*(1-$J$26)*Rampa!AK17 -> 138.7
D27: B93114 | E27: Oracle Cloud Infrastructure-Compute-Standard-E4-Memory | F27: 128 | G27: Gigabyte Per Hour | H27: 0.0015 | I27: 730 | J27: 0.05 | K27: =$F$27*$H$27*$I$27*(1-$J$27)*Rampa!B17 -> 0 | L27: =$F$27*$H$27*$I$27*(1-$J$27)*Rampa!C17 -> 133.152 | M27: =$F$27*$H$27*$I$27*(1-$J$27)*Rampa!D17 -> 133.152 | N27: =$F$27*$H$27*$I$27*(1-$J$27)*Rampa!E17 -> 133.152 | O27: =$F$27*$H$27*$I$27*(1-$J$27)*Rampa!F17 -> 133.152 | P27: =$F$27*$H$27*$I$27*(1-$J$27)*Rampa!G17 -> 133.152 | Q27: =$F$27*$H$27*$I$27*(1-$J$27)*Rampa!H17 -> 133.152 | R27: =$F$27*$H$27*$I$27*(1-$J$27)*Rampa!I17 -> 133.152 | ... AT27: =$F$27*$H$27*$I$27*(1-$J$27)*Rampa!AK17 -> 133.152
D28: B91961 | E28: Oracle Cloud Infrastructure - Block Volume Storage | F28: 413 | G28: Gigabyte Storage Capacity Per Month | H28: 0.0255 | I28: 1 | J28: 0.05 | K28: =$F$28*$H$28*$I$28*(1-$J$28)*Rampa!B17 -> 0 | L28: =$F$28*$H$28*$I$28*(1-$J$28)*Rampa!C17 -> 10.004925 | M28: =$F$28*$H$28*$I$28*(1-$J$28)*Rampa!D17 -> 10.004925 | N28: =$F$28*$H$28*$I$28*(1-$J$28)*Rampa!E17 -> 10.004925 | O28: =$F$28*$H$28*$I$28*(1-$J$28)*Rampa!F17 -> 10.004925 | P28: =$F$28*$H$28*$I$28*(1-$J$28)*Rampa!G17 -> 10.004925 | Q28: =$F$28*$H$28*$I$28*(1-$J$28)*Rampa!H17 -> 10.004925 | R28: =$F$28*$H$28*$I$28*(1-$J$28)*Rampa!I17 -> 10.004925 | ... AT28: =$F$28*$H$28*$I$28*(1-$J$28)*Rampa!AK17 -> 10.004925
D29: B91962 | E29: Oracle Cloud Infrastructure - Block Volume Performance | F29: =F28*120 -> 49560 | G29: Performance Units Per Gigabyte Per Month | H29: 0.0017 | I29: 1 | J29: 0.05 | K29: =$F$29*$H$29*$I$29*(1-$J$29)*Rampa!B17 -> 0 | L29: =$F$29*$H$29*$I$29*(1-$J$29)*Rampa!C17 -> 80.0394 | M29: =$F$29*$H$29*$I$29*(1-$J$29)*Rampa!D17 -> 80.0394 | N29: =$F$29*$H$29*$I$29*(1-$J$29)*Rampa!E17 -> 80.0394 | O29: =$F$29*$H$29*$I$29*(1-$J$29)*Rampa!F17 -> 80.0394 | P29: =$F$29*$H$29*$I$29*(1-$J$29)*Rampa!G17 -> 80.0394 | Q29: =$F$29*$H$29*$I$29*(1-$J$29)*Rampa!H17 -> 80.0394 | R29: =$F$29*$H$29*$I$29*(1-$J$29)*Rampa!I17 -> 80.0394 | ... AT29: =$F$29*$H$29*$I$29*(1-$J$29)*Rampa!AK17 -> 80.0394
C30: QA | D30: B99060 | E30: Oracle Cloud Infrastructure Database with PostgreSQL - X86 | F30: 4 | G30: OCPU Per Hour | H30: 0.098 | I30: 730 | J30: 0.05 | K30: =$F$30*$H$30*$I$30*(1-$J$30)*Rampa!B18 -> 0 | L30: =$F$30*$H$30*$I$30*(1-$J$30)*Rampa!C18 -> 271.852 | M30: =$F$30*$H$30*$I$30*(1-$J$30)*Rampa!D18 -> 271.852 | N30: =$F$30*$H$30*$I$30*(1-$J$30)*Rampa!E18 -> 271.852 | O30: =$F$30*$H$30*$I$30*(1-$J$30)*Rampa!F18 -> 271.852 | P30: =$F$30*$H$30*$I$30*(1-$J$30)*Rampa!G18 -> 271.852 | Q30: =$F$30*$H$30*$I$30*(1-$J$30)*Rampa!H18 -> 271.852 | R30: =$F$30*$H$30*$I$30*(1-$J$30)*Rampa!I18 -> 271.852 | ... AT30: =$F$30*$H$30*$I$30*(1-$J$30)*Rampa!AK18 -> 271.852
D31: B99062 | E31: Oracle Cloud Infrastructure Database Optimized Storage | F31: 100 | G31: Gigabyte Storage Capacity Per Month | H31: 0.072 | I31: 1 | J31: 0.05 | K31: =$F$31*$H$31*$I$31*(1-$J$31)*Rampa!B18 -> 0 | L31: =$F$31*$H$31*$I$31*(1-$J$31)*Rampa!C18 -> 6.84 | M31: =$F$31*$H$31*$I$31*(1-$J$31)*Rampa!D18 -> 6.84 | N31: =$F$31*$H$31*$I$31*(1-$J$31)*Rampa!E18 -> 6.84 | O31: =$F$31*$H$31*$I$31*(1-$J$31)*Rampa!F18 -> 6.84 | P31: =$F$31*$H$31*$I$31*(1-$J$31)*Rampa!G18 -> 6.84 | Q31: =$F$31*$H$31*$I$31*(1-$J$31)*Rampa!H18 -> 6.84 | R31: =$F$31*$H$31*$I$31*(1-$J$31)*Rampa!I18 -> 6.84 | ... AT31: =$F$31*$H$31*$I$31*(1-$J$31)*Rampa!AK18 -> 6.84
D32: B93113 | E32: Oracle Cloud Infrastructure-Compute-Standard-E4 | F32: 4 | G32: OCPU Per Hour | H32: 0.025 | I32: 730 | J32: 0.05 | K32: =$F$32*$H$32*$I$32*(1-$J$32)*Rampa!B18 -> 0 | L32: =$F$32*$H$32*$I$32*(1-$J$32)*Rampa!C18 -> 69.35 | M32: =$F$32*$H$32*$I$32*(1-$J$32)*Rampa!D18 -> 69.35 | N32: =$F$32*$H$32*$I$32*(1-$J$32)*Rampa!E18 -> 69.35 | O32: =$F$32*$H$32*$I$32*(1-$J$32)*Rampa!F18 -> 69.35 | P32: =$F$32*$H$32*$I$32*(1-$J$32)*Rampa!G18 -> 69.35 | Q32: =$F$32*$H$32*$I$32*(1-$J$32)*Rampa!H18 -> 69.35 | R32: =$F$32*$H$32*$I$32*(1-$J$32)*Rampa!I18 -> 69.35 | ... AT32: =$F$32*$H$32*$I$32*(1-$J$32)*Rampa!AK18 -> 69.35
D33: B93114 | E33: Oracle Cloud Infrastructure-Compute-Standard-E4-Memory | F33: 64 | G33: Gigabyte Per Hour | H33: 0.0015 | I33: 730 | J33: 0.05 | K33: =$F$33*$H$33*$I$33*(1-$J$33)*Rampa!B18 -> 0 | L33: =$F$33*$H$33*$I$33*(1-$J$33)*Rampa!C18 -> 66.576 | M33: =$F$33*$H$33*$I$33*(1-$J$33)*Rampa!D18 -> 66.576 | N33: =$F$33*$H$33*$I$33*(1-$J$33)*Rampa!E18 -> 66.576 | O33: =$F$33*$H$33*$I$33*(1-$J$33)*Rampa!F18 -> 66.576 | P33: =$F$33*$H$33*$I$33*(1-$J$33)*Rampa!G18 -> 66.576 | Q33: =$F$33*$H$33*$I$33*(1-$J$33)*Rampa!H18 -> 66.576 | R33: =$F$33*$H$33*$I$33*(1-$J$33)*Rampa!I18 -> 66.576 | ... AT33: =$F$33*$H$33*$I$33*(1-$J$33)*Rampa!AK18 -> 66.576
D34: B91961 | E34: Oracle Cloud Infrastructure - Block Volume Storage | F34: 100 | G34: Gigabyte Storage Capacity Per Month | H34: 0.0255 | I34: 1 | J34: 0.05 | K34: =$F$34*$H$34*$I$34*(1-$J$34)*Rampa!B18 -> 0 | L34: =$F$34*$H$34*$I$34*(1-$J$34)*Rampa!C18 -> 2.4225 | M34: =$F$34*$H$34*$I$34*(1-$J$34)*Rampa!D18 -> 2.4225 | N34: =$F$34*$H$34*$I$34*(1-$J$34)*Rampa!E18 -> 2.4225 | O34: =$F$34*$H$34*$I$34*(1-$J$34)*Rampa!F18 -> 2.4225 | P34: =$F$34*$H$34*$I$34*(1-$J$34)*Rampa!G18 -> 2.4225 | Q34: =$F$34*$H$34*$I$34*(1-$J$34)*Rampa!H18 -> 2.4225 | R34: =$F$34*$H$34*$I$34*(1-$J$34)*Rampa!I18 -> 2.4225 | ... AT34: =$F$34*$H$34*$I$34*(1-$J$34)*Rampa!AK18 -> 2.4225
D35: B91962 | E35: Oracle Cloud Infrastructure - Block Volume Performance | F35: =F34*120 -> 12000 | G35: Performance Units Per Gigabyte Per Month | H35: 0.0017 | I35: 1 | J35: 0.05 | K35: =$F$35*$H$35*$I$35*(1-$J$35)*Rampa!B18 -> 0 | L35: =$F$35*$H$35*$I$35*(1-$J$35)*Rampa!C18 -> 19.38 | M35: =$F$35*$H$35*$I$35*(1-$J$35)*Rampa!D18 -> 19.38 | N35: =$F$35*$H$35*$I$35*(1-$J$35)*Rampa!E18 -> 19.38 | O35: =$F$35*$H$35*$I$35*(1-$J$35)*Rampa!F18 -> 19.38 | P35: =$F$35*$H$35*$I$35*(1-$J$35)*Rampa!G18 -> 19.38 | Q35: =$F$35*$H$35*$I$35*(1-$J$35)*Rampa!H18 -> 19.38 | R35: =$F$35*$H$35*$I$35*(1-$J$35)*Rampa!I18 -> 19.38 | ... AT35: =$F$35*$H$35*$I$35*(1-$J$35)*Rampa!AK18 -> 19.38
C36: DEV | D36: B99060 | E36: Oracle Cloud Infrastructure Database with PostgreSQL - X86 | F36: 4 | G36: OCPU Per Hour | H36: 0.098 | I36: 730 | J36: 0.05 | K36: =$F$36*$H$36*$I$36*(1-$J$36)*Rampa!B19 -> 271.852 | L36: =$F$36*$H$36*$I$36*(1-$J$36)*Rampa!C19 -> 271.852 | M36: =$F$36*$H$36*$I$36*(1-$J$36)*Rampa!D19 -> 271.852 | N36: =$F$36*$H$36*$I$36*(1-$J$36)*Rampa!E19 -> 271.852 | O36: =$F$36*$H$36*$I$36*(1-$J$36)*Rampa!F19 -> 271.852 | P36: =$F$36*$H$36*$I$36*(1-$J$36)*Rampa!G19 -> 271.852 | Q36: =$F$36*$H$36*$I$36*(1-$J$36)*Rampa!H19 -> 271.852 | R36: =$F$36*$H$36*$I$36*(1-$J$36)*Rampa!I19 -> 271.852 | ... AT36: =$F$36*$H$36*$I$36*(1-$J$36)*Rampa!AK19 -> 271.852
D37: B99062 | E37: Oracle Cloud Infrastructure Database Optimized Storage | F37: 168 | G37: Gigabyte Storage Capacity Per Month | H37: 0.072 | I37: 1 | J37: 0.05 | K37: =$F$37*$H$37*$I$37*(1-$J$37)*Rampa!B19 -> 11.4912 | L37: =$F$37*$H$37*$I$37*(1-$J$37)*Rampa!C19 -> 11.4912 | M37: =$F$37*$H$37*$I$37*(1-$J$37)*Rampa!D19 -> 11.4912 | N37: =$F$37*$H$37*$I$37*(1-$J$37)*Rampa!E19 -> 11.4912 | O37: =$F$37*$H$37*$I$37*(1-$J$37)*Rampa!F19 -> 11.4912 | P37: =$F$37*$H$37*$I$37*(1-$J$37)*Rampa!G19 -> 11.4912 | Q37: =$F$37*$H$37*$I$37*(1-$J$37)*Rampa!H19 -> 11.4912 | R37: =$F$37*$H$37*$I$37*(1-$J$37)*Rampa!I19 -> 11.4912 | ... AT37: =$F$37*$H$37*$I$37*(1-$J$37)*Rampa!AK19 -> 11.4912
D38: B93113 | E38: Oracle Cloud Infrastructure-Compute-Standard-E4 | F38: 4 | G38: OCPU Per Hour | H38: 0.025 | I38: 730 | J38: 0.05 | K38: =$F$38*$H$38*$I$38*(1-$J$38)*Rampa!B19 -> 69.35 | L38: =$F$38*$H$38*$I$38*(1-$J$38)*Rampa!C19 -> 69.35 | M38: =$F$38*$H$38*$I$38*(1-$J$38)*Rampa!D19 -> 69.35 | N38: =$F$38*$H$38*$I$38*(1-$J$38)*Rampa!E19 -> 69.35 | O38: =$F$38*$H$38*$I$38*(1-$J$38)*Rampa!F19 -> 69.35 | P38: =$F$38*$H$38*$I$38*(1-$J$38)*Rampa!G19 -> 69.35 | Q38: =$F$38*$H$38*$I$38*(1-$J$38)*Rampa!H19 -> 69.35 | R38: =$F$38*$H$38*$I$38*(1-$J$38)*Rampa!I19 -> 69.35 | ... AT38: =$F$38*$H$38*$I$38*(1-$J$38)*Rampa!AK19 -> 69.35
D39: B93114 | E39: Oracle Cloud Infrastructure-Compute-Standard-E4-Memory | F39: 64 | G39: Gigabyte Per Hour | H39: 0.0015 | I39: 730 | J39: 0.05 | K39: =$F$39*$H$39*$I$39*(1-$J$39)*Rampa!B19 -> 66.576 | L39: =$F$39*$H$39*$I$39*(1-$J$39)*Rampa!C19 -> 66.576 | M39: =$F$39*$H$39*$I$39*(1-$J$39)*Rampa!D19 -> 66.576 | N39: =$F$39*$H$39*$I$39*(1-$J$39)*Rampa!E19 -> 66.576 | O39: =$F$39*$H$39*$I$39*(1-$J$39)*Rampa!F19 -> 66.576 | P39: =$F$39*$H$39*$I$39*(1-$J$39)*Rampa!G19 -> 66.576 | Q39: =$F$39*$H$39*$I$39*(1-$J$39)*Rampa!H19 -> 66.576 | R39: =$F$39*$H$39*$I$39*(1-$J$39)*Rampa!I19 -> 66.576 | ... AT39: =$F$39*$H$39*$I$39*(1-$J$39)*Rampa!AK19 -> 66.576
D40: B91961 | E40: Oracle Cloud Infrastructure - Block Volume Storage | F40: 168 | G40: Gigabyte Storage Capacity Per Month | H40: 0.0255 | I40: 1 | J40: 0.05 | K40: =$F$40*$H$40*$I$40*(1-$J$40)*Rampa!B19 -> 4.0698 | L40: =$F$40*$H$40*$I$40*(1-$J$40)*Rampa!C19 -> 4.0698 | M40: =$F$40*$H$40*$I$40*(1-$J$40)*Rampa!D19 -> 4.0698 | N40: =$F$40*$H$40*$I$40*(1-$J$40)*Rampa!E19 -> 4.0698 | O40: =$F$40*$H$40*$I$40*(1-$J$40)*Rampa!F19 -> 4.0698 | P40: =$F$40*$H$40*$I$40*(1-$J$40)*Rampa!G19 -> 4.0698 | Q40: =$F$40*$H$40*$I$40*(1-$J$40)*Rampa!H19 -> 4.0698 | R40: =$F$40*$H$40*$I$40*(1-$J$40)*Rampa!I19 -> 4.0698 | ... AT40: =$F$40*$H$40*$I$40*(1-$J$40)*Rampa!AK19 -> 4.0698
D41: B91962 | E41: Oracle Cloud Infrastructure - Block Volume Performance | F41: =F40*120 -> 20160 | G41: Performance Units Per Gigabyte Per Month | H41: 0.0017 | I41: 1 | J41: 0.05 | K41: =$F$41*$H$41*$I$41*(1-$J$41)*Rampa!B19 -> 32.5584 | L41: =$F$41*$H$41*$I$41*(1-$J$41)*Rampa!C19 -> 32.5584 | M41: =$F$41*$H$41*$I$41*(1-$J$41)*Rampa!D19 -> 32.5584 | N41: =$F$41*$H$41*$I$41*(1-$J$41)*Rampa!E19 -> 32.5584 | O41: =$F$41*$H$41*$I$41*(1-$J$41)*Rampa!F19 -> 32.5584 | P41: =$F$41*$H$41*$I$41*(1-$J$41)*Rampa!G19 -> 32.5584 | Q41: =$F$41*$H$41*$I$41*(1-$J$41)*Rampa!H19 -> 32.5584 | R41: =$F$41*$H$41*$I$41*(1-$J$41)*Rampa!I19 -> 32.5584 | ... AT41: =$F$41*$H$41*$I$41*(1-$J$41)*Rampa!AK19 -> 32.5584
K42: =SUM(K6:K41) -> 29368.642 | L42: =SUM(L6:L41) -> 35226.247 | M42: =SUM(M6:M41) -> 35226.247 | N42: =SUM(N6:N41) -> 35226.247 | O42: =SUM(O6:O41) -> 35226.247 | P42: =SUM(P6:P41) -> 35226.247 | Q42: =SUM(Q6:Q41) -> 35226.247 | R42: =SUM(R6:R41) -> 35226.247 | ... AT42: =SUM(AT6:AT41) -> 35226.247
...

Sheet AppCA
A1: Quote ID: | B1: 102763

Sheet Rampa
A2: VMWare | B2: Mes 1 | C2: Mes 2 | D2: Mes 3 | E2: Mes 4 | F2: Mes 5 | G2: Mes 6 | H2: Mes 7 | I2: Mes 8 | J2: Mes 9 | K2: Mes 10 | L2: Mes 11 | M2: Mes 12 | N2: Mes 13 | O2: Mes 14 | P2: Mes 15 | Q2: Mes 16 | R2: Mes 17 | S2: Mes 18 | T2: Mes 19 | U2: Mes 20 | V2: Mes 21 | W2: Mes 22 | X2: Mes 23 | Y2: Mes 24 | Z2: Mes 25 | AA2: Mes 26 | AB2: Mes 27 | AC2: Mes 28 | AD2: Mes 29 | AE2: Mes 30 | AF2: Mes 31 | AG2: Mes 32 | AH2: Mes 33 | AI2: Mes 34 | AJ2: Mes 35 | AK2: Mes 36
A3: VMWare - Producción | B3: =SUM(BOM_full!K6:K11) -> 28912.745 | C3: =SUM(BOM_full!L6:L11) -> 28912.745 | D3: =SUM(BOM_full!M6:M11) -> 28912.745 | E3: =SUM(BOM_full!N6:N11) -> 28912.745 | F3: =SUM(BOM_full!O6:O11) -> 28912.745 | G3: =SUM(BOM_full!P6:P11) -> 28912.745 | H3: =SUM(BOM_full!Q6:Q11) -> 28912.745 | I3: =SUM(BOM_full!R6:R11) -> 28912.745 | ... AK3: =SUM(BOM_full!AT6:AT11) -> 28912.745
A4: OKE - Produccion | B4: =SUM(BOM_full!K13:K17) -> 0 | C4: =SUM(BOM_full!L13:L17) -> 1811.6975 | D4: =SUM(BOM_full!M13:M17) -> 1811.6975 | E4: =SUM(BOM_full!N13:N17) -> 1811.6975 | F4: =SUM(BOM_full!O13:O17) -> 1811.6975 | G4: =SUM(BOM_full!P13:P17) -> 1811.6975 | H4: =SUM(BOM_full!Q13:Q17) -> 1811.6975 | I4: =SUM(BOM_full!R13:R17) -> 1811.6975 | ... AK4: =SUM(BOM_full!AT13:AT17) -> 1811.6975
A5: PostgreSQL - PRD1 | B5: =SUM(BOM_full!K18:K23) -> 0 | C5: =SUM(BOM_full!L18:L23) -> 907.212 | D5: =SUM(BOM_full!M18:M23) -> 907.212 | E5: =SUM(BOM_full!N18:N23) -> 907.212 | F5: =SUM(BOM_full!O18:O23) -> 907.212 | G5: =SUM(BOM_full!P18:P23) -> 907.212 | H5: =SUM(BOM_full!Q18:Q23) -> 907.212 | I5: =SUM(BOM_full!R18:R23) -> 907.212 | ... AK5: =SUM(BOM_full!AT18:AT23) -> 907.212
A6: PostgreSQL - PRD2 | B6: =SUM(BOM_full!K24:K29) -> 0 | C6: =SUM(BOM_full!L24:L29) -> 933.84952 | D6: =SUM(BOM_full!M24:M29) -> 933.84952 | E6: =SUM(BOM_full!N24:N29) -> 933.84952 | F6: =SUM(BOM_full!O24:O29) -> 933.84952 | G6: =SUM(BOM_full!P24:P29) -> 933.84952 | H6: =SUM(BOM_full!Q24:Q29) -> 933.84952 | I6: =SUM(BOM_full!R24:R29) -> 933.84952 | ... AK6: =SUM(BOM_full!AT24:AT29) -> 933.84952
A7: PostgreSQL - QA | B7: =SUM(BOM_full!K30:K35) -> 0 | C7: =SUM(BOM_full!L30:L35) -> 436.4205 | D7: =SUM(BOM_full!M30:M35) -> 436.4205 | E7: =SUM(BOM_full!N30:N35) -> 436.4205 | F7: =SUM(BOM_full!O30:O35) -> 436.4205 | G7: =SUM(BOM_full!P30:P35) -> 436.4205 | H7: =SUM(BOM_full!Q30:Q35) -> 436.4205 | I7: =SUM(BOM_full!R30:R35) -> 436.4205 | ... AK7: =SUM(BOM_full!AT30:AT35) -> 436.4205
A8: PostgreSQL - DEV | B8: =SUM(BOM_full!K36:K41) -> 455.8974 | C8: =SUM(BOM_full!L36:L41) -> 455.8974 | D8: =SUM(BOM_full!M36:M41) -> 455.8974 | E8: =SUM(BOM_full!N36:N41) -> 455.8974 | F8: =SUM(BOM_full!O36:O41) -> 455.8974 | G8: =SUM(BOM_full!P36:P41) -> 455.8974 | H8: =SUM(BOM_full!Q36:Q41) -> 455.8974 | I8: =SUM(BOM_full!R36:R41) -> 455.8974 | ... AK8: =SUM(BOM_full!AT36:AT41) -> 455.8974
A9: Networking - Fastconnect | B9: =BOM_full!K12 -> 0 | C9: =BOM_full!L12 -> 1768.425 | D9: =BOM_full!M12 -> 1768.425 | E9: =BOM_full!N12 -> 1768.425 | F9: =BOM_full!O12 -> 1768.425 | G9: =BOM_full!P12 -> 1768.425 | H9: =BOM_full!Q12 -> 1768.425 | I9: =BOM_full!R12 -> 1768.425 | ... AK9: =BOM_full!AT12 -> 1768.425
B10: =SUM(B3:B9) -> 29368.642 | C10: =SUM(C3:C9) -> 35226.247 | D10: =SUM(D3:D9) -> 35226.247 | E10: =SUM(E3:E9) -> 35226.247 | F10: =SUM(F3:F9) -> 35226.247 | G10: =SUM(G3:G9) -> 35226.247 | H10: =SUM(H3:H9) -> 35226.247 | I10: =SUM(I3:I9) -> 35226.247 | ... AK10: =SUM(AK3:AK9) -> 35226.247
M11: =SUM(B10:M10) -> 416857.36 | Y11: =SUM(N10:Y10) -> 422714.96 | AK11: =SUM(Z10:AK10) -> 422714.96
B13: Mes 1 | C13: Mes 2 | D13: Mes 3 | E13: Mes 4 | F13: Mes 5 | G13: Mes 6 | H13: Mes 7 | I13: Mes 8 | J13: Mes 9 | K13: Mes 10 | L13: Mes 11 | M13: Mes 12 | N13: Mes 13 | O13: Mes 14 | P13: Mes 15 | Q13: Mes 16 | R13: Mes 17 | S13: Mes 18 | T13: Mes 19 | U13: Mes 20 | V13: Mes 21 | W13: Mes 22 | X13: Mes 23 | Y13: Mes 24 | Z13: Mes 25 | AA13: Mes 26 | AB13: Mes 27 | AC13: Mes 28 | AD13: Mes 29 | AE13: Mes 30 | AF13: Mes 31 | AG13: Mes 32 | AH13: Mes 33 | AI13: Mes 34 | AJ13: Mes 35 | AK13: Mes 36
A14: OCVS - Producción | B14: 1 | C14: 1 | D14: 1 | E14: 1 | F14: 1 | G14: 1 | H14: 1 | I14: 1 | J14: 1 | K14: 1 | L14: 1 | M14: 1 | N14: 1 | O14: 1 | P14: 1 | Q14: 1 | R14: 1 | S14: 1 | T14: 1 | U14: 1 | V14: 1 | W14: 1 | X14: 1 | Y14: 1 | Z14: 1 | AA14: 1 | AB14: 1 | AC14: 1 | AD14: 1 | AE14: 1 | AF14: 1 | AG14: 1 | AH14: 1 | AI14: 1 | AJ14: 1 | AK14: 1
A15: OKE - Produccion | B15: 0 | C15: 1 | D15: 1 | E15: 1 | F15: 1 | G15: 1 | H15: 1 | I15: 1 | J15: 1 | K15: 1 | L15: 1 | M15: 1 | N15: 1 | O15: 1 | P15: 1 | Q15: 1 | R15: 1 | S15: 1 | T15: 1 | U15: 1 | V15: 1 | W15: 1 | X15: 1 | Y15: 1 | Z15: 1 | AA15: 1 | AB15: 1 | AC15: 1 | AD15: 1 | AE15: 1 | AF15: 1 | AG15: 1 | AH15: 1 | AI15: 1 | AJ15: 1 | AK15: 1
A16: PostgreSQL - PRD1 | B16: 0 | C16: 1 | D16: 1 | E16: 1 | F16: 1 | G16: 1 | H16: 1 | I16: 1 | J16: 1 | K16: 1 | L16: 1 | M16: 1 | N16: 1 | O16: 1 | P16: 1 | Q16: 1 | R16: 1 | S16: 1 | T16: 1 | U16: 1 | V16: 1 | W16: 1 | X16: 1 | Y16: 1 | Z16: 1 | AA16: 1 | AB16: 1 | AC16: 1 | AD16: 1 | AE16: 1 | AF16: 1 | AG16: 1 | AH16: 1 | AI16: 1 | AJ16: 1 | AK16: 1
A17: PostgreSQL - PRD2 | B17: 0 | C17: 1 | D17: 1 | E17: 1 | F17: 1 | G17: 1 | H17: 1 | I17: 1 | J17: 1 | K17: 1 | L17: 1 | M17: 1 | N17: 1 | O17: 1 | P17: 1 | Q17: 1 | R17: 1 | S17: 1 | T17: 1 | U17: 1 | V17: 1 | W17: 1 | X17: 1 | Y17: 1 | Z17: 1 | AA17: 1 | AB17: 1 | AC17: 1 | AD17: 1 | AE17: 1 | AF17: 1 | AG17: 1 | AH17: 1 | AI17: 1 | AJ17: 1 | AK17: 1
A18: PostgreSQL - QA | B18: 0 | C18: 1 | D18: 1 | E18: 1 | F18: 1 | G18: 1 | H18: 1 | I18: 1 | J18: 1 | K18: 1 | L18: 1 | M18: 1 | N18: 1 | O18: 1 | P18: 1 | Q18: 1 | R18: 1 | S18: 1 | T18: 1 | U18: 1 | V18: 1 | W18: 1 | X18: 1 | Y18: 1 | Z18: 1 | AA18: 1 | AB18: 1 | AC18: 1 | AD18: 1 | AE18: 1 | AF18: 1 | AG18: 1 | AH18: 1 | AI18: 1 | AJ18: 1 | AK18: 1
A19: PostgreSQL - DEV | B19: 1 | C19: 1 | D19: 1 | E19: 1 | F19: 1 | G19: 1 | H19: 1 | I19: 1 | J19: 1 | K19: 1 | L19: 1 | M19: 1 | N19: 1 | O19: 1 | P19: 1 | Q19: 1 | R19: 1 | S19: 1 | T19: 1 | U19: 1 | V19: 1 | W19: 1 | X19: 1 | Y19: 1 | Z19: 1 | AA19: 1 | AB19: 1 | AC19: 1 | AD19: 1 | AE19: 1 | AF19: 1 | AG19: 1 | AH19: 1 | AI19: 1 | AJ19: 1 | AK19: 1
A20: Networking | B20: 0 | C20: 1 | D20: 1 | E20: 1 | F20: 1 | G20: 1 | H20: 1 | I20: 1 | J20: 1 | K20: 1 | L20: 1 | M20: 1 | N20: 1 | O20: 1 | P20: 1 | Q20: 1 | R20: 1 | S20: 1 | T20: 1 | U20: 1 | V20: 1 | W20: 1 | X20: 1 | Y20: 1 | Z20: 1 | AA20: 1 | AB20: 1 | AC20: 1 | AD20: 1 | AE20: 1 | AF20: 1 | AG20: 1 | AH20: 1 | AI20: 1 | AJ20: 1 | AK20: 1

Sheet Resumen_BoM
A5: Resumen BoM
A6: Concepto | B6: Comentarios | C6: Total Año 1 | D6: Total Año 2 | E6: Total Año 3
A7: Produccion OCVS | B7: Ambiente Produccion - 4x Nodos OCVS X7 | C7: =SUM(Rampa!B3:M3) -> 346952.94 | D7: =SUM(Rampa!N3:Y3) -> 346952.94 | E7: =SUM(Rampa!Z3:AK3) -> 346952.94
A8: OCI Kubernetes Engine | B8: Ambiente Produccion - Cluster OCI Kubernetes | C8: =SUM(Rampa!B4:M4) -> 19928.673 | D8: =SUM(Rampa!N4:Y4) -> 21740.37 | E8: =SUM(Rampa!Z4:AK4) -> 21740.37
A9: PostgreSQL - Producción 1 | B9: Ambiente Produccion - PostgreSQL | C9: =SUM(Rampa!B5:M5) -> 9979.332 | D9: =SUM(Rampa!N5:Y5) -> 10886.544 | E9: =SUM(Rampa!Z5:AK5) -> 10886.544
A10: PostgreSQL - Producción 2 | B10: Ambiente Produccion - PostgreSQL | C10: =SUM(Rampa!B6:M6) -> 10272.345 | D10: =SUM(Rampa!N6:Y6) -> 11206.194 | E10: =SUM(Rampa!Z6:AK6) -> 11206.194
A11: PostgreSQL - QA | B11: Ambiente QA - PostgreSQL | C11: =SUM(Rampa!B7:M7) -> 4800.6255 | D11: =SUM(Rampa!N7:Y7) -> 5237.046 | E11: =SUM(Rampa!Z7:AK7) -> 5237.046
A12: PostgreSQL - DEV | B12: Ambiente DEV - PostgreSQL | C12: =SUM(Rampa!B8:M8) -> 5470.7688 | D12: =SUM(Rampa!N8:Y8) -> 5470.7688 | E12: =SUM(Rampa!Z8:AK8) -> 5470.7688
A13: Networking | B13: 2x Puertos FastConnect 10GB | C13: =SUM(Rampa!B9:M9) -> 19452.675 | D13: =SUM(Rampa!N9:Y9) -> 21221.1 | E13: =SUM(Rampa!Z9:AK9) -> 21221.1
B14: Total Creditos Universales OCI (USD) | C14: =SUM(C7:C13) -> 416857.36 | D14: =SUM(D7:D13) -> 422714.96 | E14: =SUM(E7:E13) -> 422714.96

Sheet Arquitectura
